---
title: "协程中的数据安全问题及解决方案"
date: "2024-02-23"
tags: ["JavaScript", "协程" ]
draft: false
description: "讨论JavaScript中协程导致的数据安全问题及其解决方案，确保代码的正确性和可靠性。"
---

# 协程也不安全？

有这么一串代码，发生了协程抢占资源的问题，导致了数据不安全的问题。

```javascript
//模拟请求获取数字
function getNumber(number) {
  return new Promise((resolve, reject) => {
    setTimeout(() => {
      resolve(number);
    }, 100);
  });
}
let count = 0;
// 将获取到的数字赋值给变量count
async function addcount(number) {
  count += await getNumber(number);
  console.log(count);
}

addcount(1);
addcount(2);
addcount(3);
```

这段代码的输出结果是：

```javascript
1
2
3
```

为什么会这样呢？协程也不安全吗，协程难道不是同一时刻只能有一个协程在执行吗？

这个问题的根本原因在于`count += await getNumber(number)`，这段代码并不是原子操作，而是分为4步：

1. 获取`count`的值
2. 交出控制权，等待`getNumber(number)`的结果
3. 将`count`和`getNumber(number)`的值相加
4. 将相加的结果赋值给`count`

因为第一步就获取了`count`的值，而`addcount(1)`、`addcount(2)`、`addcount(3)`是同步执行的，所以三个函数`count`的值是一样的。最后的结果就是`0`加`getNumber(number)`的值。

## 解决方案

使用`.then`方法或者先等待`getNumber(number)`的结果再相加，或者使用`await addcount(1)`。总之就是要保证`count`的值是在`getNumber(number)`的结果之后再相加。这种情况还不好调试，因为断点调试的时候I/O耗时会继续等待，断点执行下一步`getNumber(2)`时上一个`getNumber(1)`已经拿到值了，所以不会出现问题。但是在实际运行的时候，就会出现问题。
